Workbook
Name Slicer_Month: #N/A
Name Slicer_Region: #N/A
Name Slicer_Team: #N/A

Sheet Raw_Data
A1: Record_ID | B1: Date | C1: Team | D1: Owner | E1: Region | F1: Customer | G1: Product | H1: Lead_Source | I1: Sales_Stage | J1: Deals | K1: Deal_Value_INR | L1: Revenue_INR | M1: Tickets | N1: First_Response_Hours | O1: Resolution_Hours | P1: CSAT | Q1: Status
A2: INT-00001 | B2: 46120 | C2: Sales | D2: Ishita | E2: India | F2: Customer 220 | G2: CRM | H2: Inbound | I2: Won | J2: 1 | K2: 67500 | L2: 67500 | N2: 2 | Q2: Won
A3: INT-00002 | B3: 46201 | C3: Support | D3: Sneha | E3: USA | F3: Customer 619 | G3: WhatsApp API | J3: 0 | K3: 0 | L3: 0 | M3: 1 | N3: 6.8 | O3: 3.1 | P3: 3.9 | Q3: Closed
A4: INT-00003 | B4: 45970 | C4: Support | D4: Pooja | E4: USA | F4: Customer 672 | G4: WhatsApp API | J4: 0 | K4: 0 | L4: 0 | M4: 1 | N4: 1.6 | O4: 6.2 | P4: 3.3 | Q4: Closed
A5: INT-00004 | B5: 46042 | C5: Support | D5: Karan | E5: UK | F5: Customer 314 | G5: CRM | J5: 0 | K5: 0 | L5: 0 | M5: 1 | N5: 7.9 | O5: 8.9 | P5: 4.8 | Q5: Resolved
A6: INT-00005 | B6: 46245 | C6: Sales | D6: Aarav | E6: SEA | F6: Customer 445 | G6: Automation | H6: Inbound | I6: Proposal | J6: 1 | K6: 8000 | L6: 0 | N6: 2.6 | Q6: Proposal
A7: INT-00006 | B7: 45986 | C7: Sales | D7: Nisha | E7: UAE | F7: Customer 593 | G7: Analytics | H7: Inbound | I7: Won | J7: 1 | K7: 25100 | L7: 25100 | N7: 13.3 | Q7: Won
A8: INT-00007 | B8: 46098 | C8: Sales | D8: Diya | E8: USA | F8: Customer 517 | G8: CRM | H8: Referral | I8: Qualified | J8: 1 | K8: 16700 | L8: 0 | N8: 20.8 | Q8: Qualified
A9: INT-00008 | B9: 46025 | C9: Support | D9: Pooja | E9: UK | F9: Customer 588 | G9: Automation | J9: 0 | K9: 0 | L9: 0 | M9: 1 | N9: 1.4 | O9: 7.3 | P9: 4.2 | Q9: Closed
A10: INT-00009 | B10: 45949 | C10: Support | D10: Karan | E10: India | F10: Customer 391 | G10: CRM | J10: 0 | K10: 0 | L10: 0 | M10: 1 | N10: 4 | O10: 21.2 | P10: 4.2 | Q10: Resolved
A11: INT-00010 | B11: 46113 | C11: Support | D11: Sneha | E11: UK | F11: Customer 628 | G11: CRM | J11: 0 | K11: 0 | L11: 0 | M11: 1 | N11: 11.4 | O11: 9.5 | P11: 5 | Q11: Pending
A12: INT-00011 | B12: 45966 | C12: Sales | D12: Kabir | E12: India | F12: Customer 254 | G12: WhatsApp API | H12: Partner | I12: Negotiation | J12: 1 | K12: 27600 | L12: 0 | N12: 19.8 | Q12: Negotiation
A13: INT-00012 | B13: 46078 | C13: Support | D13: Rahul | E13: India | F13: Customer 307 | G13: CRM | J13: 0 | K13: 0 | L13: 0 | M13: 1 | N13: 6.3 | O13: 13.4 | P13: 3.5 | Q13: Pending
A14: INT-00013 | B14: 45985 | C14: Support | D14: Vivek | E14: India | F14: Customer 559 | G14: Analytics | J14: 0 | K14: 0 | L14: 0 | M14: 1 | N14: 6.4 | O14: 10.1 | P14: 3.6 | Q14: Closed
A15: INT-00014 | B15: 46163 | C15: Sales | D15: Kabir | E15: UAE | F15: Customer 259 | G15: Analytics | H15: Inbound | I15: Qualified | J15: 1 | K15: 11700 | L15: 0 | N15: 5.2 | Q15: Qualified
A16: INT-00015 | B16: 45908 | C16: Sales | D16: Kabir | E16: USA | F16: Customer 688 | G16: Automation | H16: Outbound | I16: Lost | J16: 1 | K16: 11600 | L16: 0 | N16: 23.7 | Q16: Lost
A17: INT-00016 | B17: 46009 | C17: Sales | D17: Ishita | E17: SEA | F17: Customer 533 | G17: CRM | H17: Referral | I17: Lost | J17: 1 | K17: 51900 | L17: 0 | N17: 10.5 | Q17: Lost
A18: INT-00017 | B18: 46147 | C18: Sales | D18: Kabir | E18: India | F18: Customer 537 | G18: Automation | H18: Outbound | I18: Lost | J18: 1 | K18: 25500 | L18: 0 | N18: 4.9 | Q18: Lost
A19: INT-00018 | B19: 46165 | C19: Sales | D19: Ishita | E19: USA | F19: Customer 434 | G19: CRM | H19: Website | I19: Proposal | J19: 1 | K19: 16900 | L19: 0 | N19: 19.8 | Q19: Proposal
A20: INT-00019 | B20: 46264 | C20: Sales | D20: Ishita | E20: India | F20: Customer 226 | G20: CRM | H20: Website | I20: Demo Scheduled | J20: 1 | K20: 41400 | L20: 0 | N20: 2.9 | Q20: Demo Scheduled
A21: INT-00020 | B21: 46063 | C21: Sales | D21: Kabir | E21: India | F21: Customer 041 | G21: Automation | H21: Outbound | I21: Won | J21: 1 | K21: 33200 | L21: 33200 | N21: 15.1 | Q21: Won
A22: INT-00021 | B22: 46050 | C22: Support | D22: Rahul | E22: UK | F22: Customer 620 | G22: Automation | J22: 0 | K22: 0 | L22: 0 | M22: 1 | N22: 3.1 | O22: 4.8 | P22: 3.9 | Q22: Resolved
A23: INT-00022 | B23: 45947 | C23: Sales | D23: Meera | E23: India | F23: Customer 201 | G23: Automation | H23: Inbound | I23: Demo Scheduled | J23: 1 | K23: 61800 | L23: 0 | N23: 12.5 | Q23: Demo Scheduled
A24: INT-00023 | B24: 46194 | C24: Sales | D24: Kabir | E24: India | F24: Customer 533 | G24: WhatsApp API | H24: Website | I24: Won | J24: 1 | K24: 47100 | L24: 47100 | N24: 21.7 | Q24: Won
A25: INT-00024 | B25: 45939 | C25: Sales | D25: Diya | E25: USA | F25: Customer 207 | G25: Analytics | H25: Referral | I25: Qualified | J25: 1 | K25: 16600 | L25: 0 | N25: 9.4 | Q25: Qualified
A26: INT-00025 | B26: 46042 | C26: Sales | D26: Kabir | E26: USA | F26: Customer 547 | G26: CRM | H26: Partner | I26: Proposal | J26: 1 | K26: 9400 | L26: 0 | N26: 1.5 | Q26: Proposal
A27: INT-00026 | B27: 46244 | C27: Support | D27: Vivek | E27: India | F27: Customer 614 | G27: CRM | J27: 0 | K27: 0 | L27: 0 | M27: 1 | N27: 8.5 | O27: 10.2 | P27: 4.7 | Q27: Closed
A28: INT-00027 | B28: 46106 | C28: Sales | D28: Arjun | E28: UK | F28: Customer 636 | G28: WhatsApp API | H28: Outbound | I28: Proposal | J28: 1 | K28: 16600 | L28: 0 | N28: 2.1 | Q28: Proposal
A29: INT-00028 | B29: 46186 | C29: Sales | D29: Nisha | E29: India | F29: Customer 673 | G29: Automation | H29: Inbound | I29: Qualified | J29: 1 | K29: 17800 | L29: 0 | N29: 5.8 | Q29: Qualified
A30: INT-00029 | B30: 46234 | C30: Support | D30: Sneha | E30: UK | F30: Customer 068 | G30: Analytics | J30: 0 | K30: 0 | L30: 0 | M30: 1 | N30: 8 | O30: 8.5 | P30: 4.8 | Q30: Resolved
A31: INT-00030 | B31: 46083 | C31: Sales | D31: Aarav | E31: UAE | F31: Customer 062 | G31: WhatsApp API | H31: Inbound | I31: Demo Scheduled | J31: 1 | K31: 28700 | L31: 0 | N31: 16 | Q31: Demo Scheduled
A32: INT-00031 | B32: 46204 | C32: Support | D32: Aditya | E32: USA | F32: Customer 684 | G32: Automation | J32: 0 | K32: 0 | L32: 0 | M32: 1 | N32: 6.4 | O32: 3.6 | P32: 5 | Q32: Resolved
A33: INT-00032 | B33: 46208 | C33: Sales | D33: Rohan | E33: India | F33: Customer 232 | G33: WhatsApp API | H33: Referral | I33: Won | J33: 1 | K33: 20300 | L33: 20300 | N33: 6.1 | Q33: Won
A34: INT-00033 | B34: 46248 | C34: Sales | D34: Meera | E34: India | F34: Customer 406 | G34: Automation | H34: Outbound | I34: Lost | J34: 1 | K34: 66800 | L34: 0 | N34: 12.4 | Q34: Lost
A35: INT-00034 | B35: 45987 | C35: Support | D35: Aditya | E35: India | F35: Customer 214 | G35: CRM | J35: 0 | K35: 0 | L35: 0 | M35: 1 | N35: 0.6 | O35: 12.5 | P35: 4.6 | Q35: Resolved
A36: INT-00035 | B36: 46262 | C36: Support | D36: Karan | E36: SEA | F36: Customer 093 | G36: WhatsApp API | J36: 0 | K36: 0 | L36: 0 | M36: 1 | N36: 2.4 | O36: 2.8 | P36: 4.3 | Q36: Resolved
A37: INT-00036 | B37: 46041 | C37: Support | D37: Ananya | E37: UAE | F37: Customer 049 | G37: CRM | J37: 0 | K37: 0 | L37: 0 | M37: 1 | N37: 10 | O37: 5.4 | P37: 4.7 | Q37: Resolved
A38: INT-00037 | B38: 46145 | C38: Sales | D38: Diya | E38: UAE | F38: Customer 318 | G38: Analytics | H38: Inbound | I38: Proposal | J38: 1 | K38: 39400 | L38: 0 | N38: 2.5 | Q38: Proposal
A39: INT-00038 | B39: 45941 | C39: Sales | D39: Arjun | E39: USA | F39: Customer 571 | G39: CRM | H39: Referral | I39: Won | J39: 1 | K39: 21000 | L39: 21000 | N39: 22.3 | Q39: Won
A40: INT-00039 | B40: 45945 | C40: Support | D40: Rahul | E40: India | F40: Customer 620 | G40: WhatsApp API | J40: 0 | K40: 0 | L40: 0 | M40: 1 | N40: 10.9 | O40: 12.2 | P40: 3.7 | Q40: Resolved
...

Sheet cleaned
A1: Record_ID | B1: Date | C1: Team | D1: Owner | E1: Region | F1: Customer | G1: Product | H1: Lead_Source | I1: Sales_Stage | J1: Deals | K1: Deal_Value_INR | L1: Revenue_INR | M1: Tickets | N1: First_Response_Hours | O1: Resolution_Hours | P1: CSAT | Q1: Status | R1: Month | S1: YEAR
A2: INT-00001 | B2: 46120 | C2: Sales | D2: Ishita | E2: India | F2: Customer 220 | G2: CRM | H2: Inbound | I2: Won | J2: 1 | K2: 67500 | L2: 67500 | N2: 2 | Q2: Won | R2: =TEXT(Table1[[#This Row],[Date]],"mmm yyyy") -> Apr 2026 | S2: =YEAR(Table1[[#This Row],[Date]]) -> 2026
A3: INT-00002 | B3: 46201 | C3: Support | D3: Sneha | E3: USA | F3: Customer 619 | G3: WhatsApp API | J3: 0 | K3: 0 | L3: 0 | M3: 1 | N3: 6.8 | O3: 3.1 | P3: 3.9 | Q3: Closed | R3: =TEXT(Table1[[#This Row],[Date]],"mmm yyyy") -> Jun 2026 | S3: =YEAR(Table1[[#This Row],[Date]]) -> 2026
A4: INT-00003 | B4: 45970 | C4: Support | D4: Pooja | E4: USA | F4: Customer 672 | G4: WhatsApp API | J4: 0 | K4: 0 | L4: 0 | M4: 1 | N4: 1.6 | O4: 6.2 | P4: 3.3 | Q4: Closed | R4: =TEXT(Table1[[#This Row],[Date]],"mmm yyyy") -> Nov 2025 | S4: =YEAR(Table1[[#This Row],[Date]]) -> 2025
A5: INT-00004 | B5: 46042 | C5: Support | D5: Karan | E5: UK | F5: Customer 314 | G5: CRM | J5: 0 | K5: 0 | L5: 0 | M5: 1 | N5: 7.9 | O5: 8.9 | P5: 4.8 | Q5: Resolved | R5: =TEXT(Table1[[#This Row],[Date]],"mmm yyyy") -> Jan 2026 | S5: =YEAR(Table1[[#This Row],[Date]]) -> 2026
A6: INT-00005 | B6: 46245 | C6: Sales | D6: Aarav | E6: SEA | F6: Customer 445 | G6: Automation | H6: Inbound | I6: Proposal | J6: 1 | K6: 8000 | L6: 0 | N6: 2.6 | Q6: Proposal | R6: =TEXT(Table1[[#This Row],[Date]],"mmm yyyy") -> Aug 2026 | S6: =YEAR(Table1[[#This Row],[Date]]) -> 2026
A7: INT-00006 | B7: 45986 | C7: Sales | D7: Nisha | E7: UAE | F7: Customer 593 | G7: Analytics | H7: Inbound | I7: Won | J7: 1 | K7: 25100 | L7: 25100 | N7: 13.3 | Q7: Won | R7: =TEXT(Table1[[#This Row],[Date]],"mmm yyyy") -> Nov 2025 | S7: =YEAR(Table1[[#This Row],[Date]]) -> 2025
A8: INT-00007 | B8: 46098 | C8: Sales | D8: Diya | E8: USA | F8: Customer 517 | G8: CRM | H8: Referral | I8: Qualified | J8: 1 | K8: 16700 | L8: 0 | N8: 20.8 | Q8: Qualified | R8: =TEXT(Table1[[#This Row],[Date]],"mmm yyyy") -> Mar 2026 | S8: =YEAR(Table1[[#This Row],[Date]]) -> 2026
A9: INT-00008 | B9: 46025 | C9: Support | D9: Pooja | E9: UK | F9: Customer 588 | G9: Automation | J9: 0 | K9: 0 | L9: 0 | M9: 1 | N9: 1.4 | O9: 7.3 | P9: 4.2 | Q9: Closed | R9: =TEXT(Table1[[#This Row],[Date]],"mmm yyyy") -> Jan 2026 | S9: =YEAR(Table1[[#This Row],[Date]]) -> 2026
A10: INT-00009 | B10: 45949 | C10: Support | D10: Karan | E10: India | F10: Customer 391 | G10: CRM | J10: 0 | K10: 0 | L10: 0 | M10: 1 | N10: 4 | O10: 21.2 | P10: 4.2 | Q10: Resolved | R10: =TEXT(Table1[[#This Row],[Date]],"mmm yyyy") -> Oct 2025 | S10: =YEAR(Table1[[#This Row],[Date]]) -> 2025
A11: INT-00010 | B11: 46113 | C11: Support | D11: Sneha | E11: UK | F11: Customer 628 | G11: CRM | J11: 0 | K11: 0 | L11: 0 | M11: 1 | N11: 11.4 | O11: 9.5 | P11: 5 | Q11: Pending | R11: =TEXT(Table1[[#This Row],[Date]],"mmm yyyy") -> Apr 2026 | S11: =YEAR(Table1[[#This Row],[Date]]) -> 2026
A12: INT-00011 | B12: 45966 | C12: Sales | D12: Kabir | E12: India | F12: Customer 254 | G12: WhatsApp API | H12: Partner | I12: Negotiation | J12: 1 | K12: 27600 | L12: 0 | N12: 19.8 | Q12: Negotiation | R12: =TEXT(Table1[[#This Row],[Date]],"mmm yyyy") -> Nov 2025 | S12: =YEAR(Table1[[#This Row],[Date]]) -> 2025
A13: INT-00012 | B13: 46078 | C13: Support | D13: Rahul | E13: India | F13: Customer 307 | G13: CRM | J13: 0 | K13: 0 | L13: 0 | M13: 1 | N13: 6.3 | O13: 13.4 | P13: 3.5 | Q13: Pending | R13: =TEXT(Table1[[#This Row],[Date]],"mmm yyyy") -> Feb 2026 | S13: =YEAR(Table1[[#This Row],[Date]]) -> 2026
A14: INT-00013 | B14: 45985 | C14: Support | D14: Vivek | E14: India | F14: Customer 559 | G14: Analytics | J14: 0 | K14: 0 | L14: 0 | M14: 1 | N14: 6.4 | O14: 10.1 | P14: 3.6 | Q14: Closed | R14: =TEXT(Table1[[#This Row],[Date]],"mmm yyyy") -> Nov 2025 | S14: =YEAR(Table1[[#This Row],[Date]]) -> 2025
A15: INT-00014 | B15: 46163 | C15: Sales | D15: Kabir | E15: UAE | F15: Customer 259 | G15: Analytics | H15: Inbound | I15: Qualified | J15: 1 | K15: 11700 | L15: 0 | N15: 5.2 | Q15: Qualified | R15: =TEXT(Table1[[#This Row],[Date]],"mmm yyyy") -> May 2026 | S15: =YEAR(Table1[[#This Row],[Date]]) -> 2026
A16: INT-00015 | B16: 45908 | C16: Sales | D16: Kabir | E16: USA | F16: Customer 688 | G16: Automation | H16: Outbound | I16: Lost | J16: 1 | K16: 11600 | L16: 0 | N16: 23.7 | Q16: Lost | R16: =TEXT(Table1[[#This Row],[Date]],"mmm yyyy") -> Sep 2025 | S16: =YEAR(Table1[[#This Row],[Date]]) -> 2025
A17: INT-00016 | B17: 46009 | C17: Sales | D17: Ishita | E17: SEA | F17: Customer 533 | G17: CRM | H17: Referral | I17: Lost | J17: 1 | K17: 51900 | L17: 0 | N17: 10.5 | Q17: Lost | R17: =TEXT(Table1[[#This Row],[Date]],"mmm yyyy") -> Dec 2025 | S17: =YEAR(Table1[[#This Row],[Date]]) -> 2025
A18: INT-00017 | B18: 46147 | C18: Sales | D18: Kabir | E18: India | F18: Customer 537 | G18: Automation | H18: Outbound | I18: Lost | J18: 1 | K18: 25500 | L18: 0 | N18: 4.9 | Q18: Lost | R18: =TEXT(Table1[[#This Row],[Date]],"mmm yyyy") -> May 2026 | S18: =YEAR(Table1[[#This Row],[Date]]) -> 2026
A19: INT-00018 | B19: 46165 | C19: Sales | D19: Ishita | E19: USA | F19: Customer 434 | G19: CRM | H19: Website | I19: Proposal | J19: 1 | K19: 16900 | L19: 0 | N19: 19.8 | Q19: Proposal | R19: =TEXT(Table1[[#This Row],[Date]],"mmm yyyy") -> May 2026 | S19: =YEAR(Table1[[#This Row],[Date]]) -> 2026
A20: INT-00019 | B20: 46264 | C20: Sales | D20: Ishita | E20: India | F20: Customer 226 | G20: CRM | H20: Website | I20: Demo Scheduled | J20: 1 | K20: 41400 | L20: 0 | N20: 2.9 | Q20: Demo Scheduled | R20: =TEXT(Table1[[#This Row],[Date]],"mmm yyyy") -> Aug 2026 | S20: =YEAR(Table1[[#This Row],[Date]]) -> 2026
A21: INT-00020 | B21: 46063 | C21: Sales | D21: Kabir | E21: India | F21: Customer 041 | G21: Automation | H21: Outbound | I21: Won | J21: 1 | K21: 33200 | L21: 33200 | N21: 15.1 | Q21: Won | R21: =TEXT(Table1[[#This Row],[Date]],"mmm yyyy") -> Feb 2026 | S21: =YEAR(Table1[[#This Row],[Date]]) -> 2026
A22: INT-00021 | B22: 46050 | C22: Support | D22: Rahul | E22: UK | F22: Customer 620 | G22: Automation | J22: 0 | K22: 0 | L22: 0 | M22: 1 | N22: 3.1 | O22: 4.8 | P22: 3.9 | Q22: Resolved | R22: =TEXT(Table1[[#This Row],[Date]],"mmm yyyy") -> Jan 2026 | S22: =YEAR(Table1[[#This Row],[Date]]) -> 2026
A23: INT-00022 | B23: 45947 | C23: Sales | D23: Meera | E23: India | F23: Customer 201 | G23: Automation | H23: Inbound | I23: Demo Scheduled | J23: 1 | K23: 61800 | L23: 0 | N23: 12.5 | Q23: Demo Scheduled | R23: =TEXT(Table1[[#This Row],[Date]],"mmm yyyy") -> Oct 2025 | S23: =YEAR(Table1[[#This Row],[Date]]) -> 2025
A24: INT-00023 | B24: 46194 | C24: Sales | D24: Kabir | E24: India | F24: Customer 533 | G24: WhatsApp API | H24: Website | I24: Won | J24: 1 | K24: 47100 | L24: 47100 | N24: 21.7 | Q24: Won | R24: =TEXT(Table1[[#This Row],[Date]],"mmm yyyy") -> Jun 2026 | S24: =YEAR(Table1[[#This Row],[Date]]) -> 2026
A25: INT-00024 | B25: 45939 | C25: Sales | D25: Diya | E25: USA | F25: Customer 207 | G25: Analytics | H25: Referral | I25: Qualified | J25: 1 | K25: 16600 | L25: 0 | N25: 9.4 | Q25: Qualified | R25: =TEXT(Table1[[#This Row],[Date]],"mmm yyyy") -> Oct 2025 | S25: =YEAR(Table1[[#This Row],[Date]]) -> 2025
A26: INT-00025 | B26: 46042 | C26: Sales | D26: Kabir | E26: USA | F26: Customer 547 | G26: CRM | H26: Partner | I26: Proposal | J26: 1 | K26: 9400 | L26: 0 | N26: 1.5 | Q26: Proposal | R26: =TEXT(Table1[[#This Row],[Date]],"mmm yyyy") -> Jan 2026 | S26: =YEAR(Table1[[#This Row],[Date]]) -> 2026
A27: INT-00026 | B27: 46244 | C27: Support | D27: Vivek | E27: India | F27: Customer 614 | G27: CRM | J27: 0 | K27: 0 | L27: 0 | M27: 1 | N27: 8.5 | O27: 10.2 | P27: 4.7 | Q27: Closed | R27: =TEXT(Table1[[#This Row],[Date]],"mmm yyyy") -> Aug 2026 | S27: =YEAR(Table1[[#This Row],[Date]]) -> 2026
A28: INT-00027 | B28: 46106 | C28: Sales | D28: Arjun | E28: UK | F28: Customer 636 | G28: WhatsApp API | H28: Outbound | I28: Proposal | J28: 1 | K28: 16600 | L28: 0 | N28: 2.1 | Q28: Proposal | R28: =TEXT(Table1[[#This Row],[Date]],"mmm yyyy") -> Mar 2026 | S28: =YEAR(Table1[[#This Row],[Date]]) -> 2026
A29: INT-00028 | B29: 46186 | C29: Sales | D29: Nisha | E29: India | F29: Customer 673 | G29: Automation | H29: Inbound | I29: Qualified | J29: 1 | K29: 17800 | L29: 0 | N29: 5.8 | Q29: Qualified | R29: =TEXT(Table1[[#This Row],[Date]],"mmm yyyy") -> Jun 2026 | S29: =YEAR(Table1[[#This Row],[Date]]) -> 2026
A30: INT-00029 | B30: 46234 | C30: Support | D30: Sneha | E30: UK | F30: Customer 068 | G30: Analytics | J30: 0 | K30: 0 | L30: 0 | M30: 1 | N30: 8 | O30: 8.5 | P30: 4.8 | Q30: Resolved | R30: =TEXT(Table1[[#This Row],[Date]],"mmm yyyy") -> Jul 2026 | S30: =YEAR(Table1[[#This Row],[Date]]) -> 2026
A31: INT-00030 | B31: 46083 | C31: Sales | D31: Aarav | E31: UAE | F31: Customer 062 | G31: WhatsApp API | H31: Inbound | I31: Demo Scheduled | J31: 1 | K31: 28700 | L31: 0 | N31: 16 | Q31: Demo Scheduled | R31: =TEXT(Table1[[#This Row],[Date]],"mmm yyyy") -> Mar 2026 | S31: =YEAR(Table1[[#This Row],[Date]]) -> 2026
A32: INT-00031 | B32: 46204 | C32: Support | D32: Aditya | E32: USA | F32: Customer 684 | G32: Automation | J32: 0 | K32: 0 | L32: 0 | M32: 1 | N32: 6.4 | O32: 3.6 | P32: 5 | Q32: Resolved | R32: =TEXT(Table1[[#This Row],[Date]],"mmm yyyy") -> Jul 2026 | S32: =YEAR(Table1[[#This Row],[Date]]) -> 2026
A33: INT-00032 | B33: 46208 | C33: Sales | D33: Rohan | E33: India | F33: Customer 232 | G33: WhatsApp API | H33: Referral | I33: Won | J33: 1 | K33: 20300 | L33: 20300 | N33: 6.1 | Q33: Won | R33: =TEXT(Table1[[#This Row],[Date]],"mmm yyyy") -> Jul 2026 | S33: =YEAR(Table1[[#This Row],[Date]]) -> 2026
A34: INT-00033 | B34: 46248 | C34: Sales | D34: Meera | E34: India | F34: Customer 406 | G34: Automation | H34: Outbound | I34: Lost | J34: 1 | K34: 66800 | L34: 0 | N34: 12.4 | Q34: Lost | R34: =TEXT(Table1[[#This Row],[Date]],"mmm yyyy") -> Aug 2026 | S34: =YEAR(Table1[[#This Row],[Date]]) -> 2026
A35: INT-00034 | B35: 45987 | C35: Support | D35: Aditya | E35: India | F35: Customer 214 | G35: CRM | J35: 0 | K35: 0 | L35: 0 | M35: 1 | N35: 0.6 | O35: 12.5 | P35: 4.6 | Q35: Resolved | R35: =TEXT(Table1[[#This Row],[Date]],"mmm yyyy") -> Nov 2025 | S35: =YEAR(Table1[[#This Row],[Date]]) -> 2025
A36: INT-00035 | B36: 46262 | C36: Support | D36: Karan | E36: SEA | F36: Customer 093 | G36: WhatsApp API | J36: 0 | K36: 0 | L36: 0 | M36: 1 | N36: 2.4 | O36: 2.8 | P36: 4.3 | Q36: Resolved | R36: =TEXT(Table1[[#This Row],[Date]],"mmm yyyy") -> Aug 2026 | S36: =YEAR(Table1[[#This Row],[Date]]) -> 2026
A37: INT-00036 | B37: 46041 | C37: Support | D37: Ananya | E37: UAE | F37: Customer 049 | G37: CRM | J37: 0 | K37: 0 | L37: 0 | M37: 1 | N37: 10 | O37: 5.4 | P37: 4.7 | Q37: Resolved | R37: =TEXT(Table1[[#This Row],[Date]],"mmm yyyy") -> Jan 2026 | S37: =YEAR(Table1[[#This Row],[Date]]) -> 2026
A38: INT-00037 | B38: 46145 | C38: Sales | D38: Diya | E38: UAE | F38: Customer 318 | G38: Analytics | H38: Inbound | I38: Proposal | J38: 1 | K38: 39400 | L38: 0 | N38: 2.5 | Q38: Proposal | R38: =TEXT(Table1[[#This Row],[Date]],"mmm yyyy") -> May 2026 | S38: =YEAR(Table1[[#This Row],[Date]]) -> 2026
A39: INT-00038 | B39: 45941 | C39: Sales | D39: Arjun | E39: USA | F39: Customer 571 | G39: CRM | H39: Referral | I39: Won | J39: 1 | K39: 21000 | L39: 21000 | N39: 22.3 | Q39: Won | R39: =TEXT(Table1[[#This Row],[Date]],"mmm yyyy") -> Oct 2025 | S39: =YEAR(Table1[[#This Row],[Date]]) -> 2025
A40: INT-00039 | B40: 45945 | C40: Support | D40: Rahul | E40: India | F40: Customer 620 | G40: WhatsApp API | J40: 0 | K40: 0 | L40: 0 | M40: 1 | N40: 10.9 | O40: 12.2 | P40: 3.7 | Q40: Resolved | R40: =TEXT(Table1[[#This Row],[Date]],"mmm yyyy") -> Oct 2025 | S40: =YEAR(Table1[[#This Row],[Date]]) -> 2025
...

Sheet summary
A1: Checking Blank Cells | E1: Sales KPI | H1: Support KPI
A3: Column Name | B3: Total Blank Cells | E3: Total Deals | F3: =SUMIF(Table1[Team],"Sales",Table1[Deals]) -> 1089 | H3: Total Tickets | I3: =SUMIFS(Table1[Tickets],Table1[Team],"Support") -> 911
A4: Record_ID | B4: =COUNTBLANK(Raw_Data!A2:A2001) -> 0 | E4: Won Deals | F4: =COUNTIFS(Table1[Team],"Sales",Table1[Sales_Stage],"Won") -> 237 | H4: Average First Response (Hours) | I4: =AVERAGEIFS(Table1[First_Response_Hours],Table1[Team],"Support") -> 6.0004391
A5: Date | B5: =COUNTBLANK(Raw_Data!B2:B2001) -> 0 | E5: Total Deal Value | F5: =SUMIFS(Table1[Deal_Value_INR],Table1[Team],"Sales") -> 31609200 | H5: Average Resolution (Hours) | I5: =AVERAGEIFS(Table1[Resolution_Hours],Table1[Team],"Support") -> 8.7686059
A6: Team | B6: =COUNTBLANK(Raw_Data!C2:C2001) -> 0 | E6: Total Revenue | F6: =SUMIFS(Table1[Revenue_INR],Table1[Team],"Sales") -> 6835500 | H6: Average CSAT | I6: =AVERAGEIFS(Table1[CSAT],Table1[Team],"Support") -> 4.0412733
A7: Owner | B7: =COUNTBLANK(Raw_Data!D2:D2001) -> 0 | E7: Win Rate | F7: =F4/F3 -> 0.21763085 | H7: Closed Tickets | I7: =COUNTIFS(Table1[Team],"Support",Table1[Status],"Closed") -> 218
A8: Region | B8: =COUNTBLANK(Raw_Data!E2:E2001) -> 0 | E8: Lost Deals | F8: =COUNTIFS(Table1[Status],"Lost",Table1[Team],"Sales") -> 146 | H8: Resolved Tickets | I8: =COUNTIFS(Table1[Team],"Support",Table1[Status],"Resolved") -> 445 | K8: Support Status | L8: Record Count
A9: Customer | B9: =COUNTBLANK(Raw_Data!F2:F2001) -> 0 | K9: Closed | L9: =COUNTIFS(Table1[Team],"Support",Table1[Status],Table14[[#This Row],[Support Status]]) -> 218
A10: Product | B10: =COUNTBLANK(Raw_Data!G2:G2001) -> 0 | K10: Resolved | L10: =COUNTIFS(Table1[Team],"Support",Table1[Status],Table14[[#This Row],[Support Status]]) -> 445
A11: Lead_Source | B11: =COUNTBLANK(Raw_Data!H2:H2001) -> 911 | K11: Pending | L11: =COUNTIFS(Table1[Team],"Support",Table1[Status],Table14[[#This Row],[Support Status]]) -> 156
A12: Sales_Stage | B12: =COUNTBLANK(Raw_Data!I2:I2001) -> 911 | K12: Escalated | L12: =COUNTIFS(Table1[Team],"Support",Table1[Status],Table14[[#This Row],[Support Status]]) -> 92
A13: Deals | B13: =COUNTBLANK(Raw_Data!J2:J2001) -> 0
A14: Deal_Value_INR | B14: =COUNTBLANK(Raw_Data!K2:K2001) -> 0
A15: Revenue_INR | B15: =COUNTBLANK(Raw_Data!L2:L2001) -> 0 | E15: Month | F15: Sales Revenue
A16: Tickets | B16: =COUNTBLANK(Raw_Data!M2:M2001) -> 1089 | E16: 45901 | F16: =SUMIFS(Table1[Revenue_INR],Table1[Team],"Sales",Table1[Month],E16) -> 196300 | L16: Sales Stage | M16: Record Count
A17: First_Response_Hours | B17: =COUNTBLANK(Raw_Data!N2:N2001) -> 1 | E17: 45931 | F17: =SUMIFS(Table1[Revenue_INR],Table1[Team],"Sales",Table1[Month],E17) -> 544000 | H17: Lost Deals By Lead Source | L17: Won | M17: =COUNTIFS(Table1[Team],"Sales",Table1[Sales_Stage],summary!L17) -> 237
A18: Resolution_Hours | B18: =COUNTBLANK(Raw_Data!O2:O2001) -> 1089 | E18: 45962 | F18: =SUMIFS(Table1[Revenue_INR],Table1[Team],"Sales",Table1[Month],E18) -> 709100 | L18: Proposal | M18: =COUNTIFS(Table1[Team],"Sales",Table1[Sales_Stage],summary!L18) -> 245
A19: CSAT | B19: =COUNTBLANK(Raw_Data!P2:P2001) -> 1089 | E19: 45992 | F19: =SUMIFS(Table1[Revenue_INR],Table1[Team],"Sales",Table1[Month],E19) -> 565700 | H19: Inbound | I19: =COUNTIFS(Table1[Status],"Lost",Table1[Lead_Source],summary!H19) -> 42 | L19: Qualified | M19: =COUNTIFS(Table1[Team],"Sales",Table1[Sales_Stage],summary!L19) -> 160
A20: Status | B20: =COUNTBLANK(Raw_Data!Q2:Q2001) -> 0 | E20: 46023 | F20: =SUMIFS(Table1[Revenue_INR],Table1[Team],"Sales",Table1[Month],E20) -> 382000 | H20: Referral | I20: =COUNTIFS(Table1[Status],"Lost",Table1[Lead_Source],summary!H20) -> 23 | L20: Negotiation | M20: =COUNTIFS(Table1[Team],"Sales",Table1[Sales_Stage],summary!L20) -> 152
E21: 46054 | F21: =SUMIFS(Table1[Revenue_INR],Table1[Team],"Sales",Table1[Month],E21) -> 448100 | H21: Partner | I21: =COUNTIFS(Table1[Status],"Lost",Table1[Lead_Source],summary!H21) -> 13 | L21: Lost | M21: =COUNTIFS(Table1[Team],"Sales",Table1[Sales_Stage],summary!L21) -> 146
E22: 46082 | F22: =SUMIFS(Table1[Revenue_INR],Table1[Team],"Sales",Table1[Month],E22) -> 713700 | H22: Outbound | I22: =COUNTIFS(Table1[Status],"Lost",Table1[Lead_Source],summary!H22) -> 41 | L22: Demo Scheduled | M22: =COUNTIFS(Table1[Team],"Sales",Table1[Sales_Stage],summary!L22) -> 149
E23: 46113 | F23: =SUMIFS(Table1[Revenue_INR],Table1[Team],"Sales",Table1[Month],E23) -> 857200 | H23: Website | I23: =COUNTIFS(Table1[Status],"Lost",Table1[Lead_Source],summary!H23) -> 27
E24: 46143 | F24: =SUMIFS(Table1[Revenue_INR],Table1[Team],"Sales",Table1[Month],E24) -> 379300
E25: 46174 | F25: =SUMIFS(Table1[Revenue_INR],Table1[Team],"Sales",Table1[Month],E25) -> 383100
E26: 46204 | F26: =SUMIFS(Table1[Revenue_INR],Table1[Team],"Sales",Table1[Month],E26) -> 1100700
E27: 46235 | F27: =SUMIFS(Table1[Revenue_INR],Table1[Team],"Sales",Table1[Month],E27) -> 556300
H30: Support Owner | I30: Total Tickets | J30: Avg Response Hours | K30: Avg Resolution Hours | L30: Avg CSAT
H31: Sneha | I31: =SUMIFS(Table1[Tickets],Table1[Team],"Support",Table1[Owner],H31) -> 98 | J31: =AVERAGEIFS(Table1[First_Response_Hours],Table1[Team],"Support",Table1[Owner],H31) -> 6.1183673 | K31: =AVERAGEIFS(Table1[Resolution_Hours],Table1[Team],"Support",Table1[Owner],H31) -> 8.7897959 | L31: =AVERAGEIFS(Table1[CSAT],Table1[Team],"Support",Table1[Owner],H31) -> 4.0867347
A32: Owner | B32: Sales Revenue | H32: Pooja | I32: =SUMIFS(Table1[Tickets],Table1[Team],"Support",Table1[Owner],H32) -> 111 | J32: =AVERAGEIFS(Table1[First_Response_Hours],Table1[Team],"Support",Table1[Owner],H32) -> 6.0864865 | K32: =AVERAGEIFS(Table1[Resolution_Hours],Table1[Team],"Support",Table1[Owner],H32) -> 7.8036036 | L32: =AVERAGEIFS(Table1[CSAT],Table1[Team],"Support",Table1[Owner],H32) -> 4.0558559
A33: =[1]summary!J10 -> Ishita | B33: =SUMIFS(Table1[Revenue_INR],Table1[Team],"Sales",Table1[Owner],Table5[[#This Row],[Owner]]) -> 1049400 | H33: Karan | I33: =SUMIFS(Table1[Tickets],Table1[Team],"Support",Table1[Owner],H33) -> 106 | J33: =AVERAGEIFS(Table1[First_Response_Hours],Table1[Team],"Support",Table1[Owner],H33) -> 6.045283 | K33: =AVERAGEIFS(Table1[Resolution_Hours],Table1[Team],"Support",Table1[Owner],H33) -> 8.9509434 | L33: =AVERAGEIFS(Table1[CSAT],Table1[Team],"Support",Table1[Owner],H33) -> 4.0283019
A34: =[1]summary!J11 -> Aarav | B34: =SUMIFS(Table1[Revenue_INR],Table1[Team],"Sales",Table1[Owner],Table5[[#This Row],[Owner]]) -> 746200 | H34: Rahul | I34: =SUMIFS(Table1[Tickets],Table1[Team],"Support",Table1[Owner],H34) -> 115 | J34: =AVERAGEIFS(Table1[First_Response_Hours],Table1[Team],"Support",Table1[Owner],H34) -> 5.7382609 | K34: =AVERAGEIFS(Table1[Resolution_Hours],Table1[Team],"Support",Table1[Owner],H34) -> 8.8373913 | L34: =AVERAGEIFS(Table1[CSAT],Table1[Team],"Support",Table1[Owner],H34) -> 4.1573913
A35: =[1]summary!J12 -> Nisha | B35: =SUMIFS(Table1[Revenue_INR],Table1[Team],"Sales",Table1[Owner],Table5[[#This Row],[Owner]]) -> 894100 | H35: Vivek | I35: =SUMIFS(Table1[Tickets],Table1[Team],"Support",Table1[Owner],H35) -> 109 | J35: =AVERAGEIFS(Table1[First_Response_Hours],Table1[Team],"Support",Table1[Owner],H35) -> 5.8522936 | K35: =AVERAGEIFS(Table1[Resolution_Hours],Table1[Team],"Support",Table1[Owner],H35) -> 9.1247706 | L35: =AVERAGEIFS(Table1[CSAT],Table1[Team],"Support",Table1[Owner],H35) -> 4.1110092
A36: =[1]summary!J13 -> Diya | B36: =SUMIFS(Table1[Revenue_INR],Table1[Team],"Sales",Table1[Owner],Table5[[#This Row],[Owner]]) -> 1069600 | H36: Aditya | I36: =SUMIFS(Table1[Tickets],Table1[Team],"Support",Table1[Owner],H36) -> 125 | J36: =AVERAGEIFS(Table1[First_Response_Hours],Table1[Team],"Support",Table1[Owner],H36) -> 6.076 | K36: =AVERAGEIFS(Table1[Resolution_Hours],Table1[Team],"Support",Table1[Owner],H36) -> 8.2144 | L36: =AVERAGEIFS(Table1[CSAT],Table1[Team],"Support",Table1[Owner],H36) -> 3.9704
A37: =[1]summary!J14 -> Kabir | B37: =SUMIFS(Table1[Revenue_INR],Table1[Team],"Sales",Table1[Owner],Table5[[#This Row],[Owner]]) -> 1308200 | H37: Ananya | I37: =SUMIFS(Table1[Tickets],Table1[Team],"Support",Table1[Owner],H37) -> 114 | J37: =AVERAGEIFS(Table1[First_Response_Hours],Table1[Team],"Support",Table1[Owner],H37) -> 6.2087719 | K37: =AVERAGEIFS(Table1[Resolution_Hours],Table1[Team],"Support",Table1[Owner],H37) -> 9.022807 | L37: =AVERAGEIFS(Table1[CSAT],Table1[Team],"Support",Table1[Owner],H37) -> 4.054386
A38: =[1]summary!J15 -> Meera | B38: =SUMIFS(Table1[Revenue_INR],Table1[Team],"Sales",Table1[Owner],Table5[[#This Row],[Owner]]) -> 617000 | H38: Priya | I38: =SUMIFS(Table1[Tickets],Table1[Team],"Support",Table1[Owner],H38) -> 133 | J38: =AVERAGEIFS(Table1[First_Response_Hours],Table1[Team],"Support",Table1[Owner],H38) -> 5.9045113 | K38: =AVERAGEIFS(Table1[Resolution_Hours],Table1[Team],"Support",Table1[Owner],H38) -> 9.3646617 | L38: =AVERAGEIFS(Table1[CSAT],Table1[Team],"Support",Table1[Owner],H38) -> 3.9037594
A39: =[1]summary!J16 -> Arjun | B39: =SUMIFS(Table1[Revenue_INR],Table1[Team],"Sales",Table1[Owner],Table5[[#This Row],[Owner]]) -> 587800
A40: =[1]summary!J17 -> Rohan | B40: =SUMIFS(Table1[Revenue_INR],Table1[Team],"Sales",Table1[Owner],Table5[[#This Row],[Owner]]) -> 563200
A52: {=_xlfn.UNIQUE(_xlfn._xlws.FILTER(Table1[Owner],Table1[Team]="Sales"))} -> Ishita
A53: Aarav
A54: Nisha
...

Sheet DASHBOARD
A1: SALES & CUSTOMER SUPPORT INSIGHTS
A3: TOTAL REVENUE | C3: WIN RATE | E3: WON DEALS | G3: AVG RESPONSE TIME | I3: AVG CSAT
A4: =summary!F6 -> 6835500 | C4: =summary!F7 -> 0.21763085 | E4: =summary!F4 -> 237 | G4: =summary!I4 -> 6.0004391 | I4: =summary!I6 -> 4.0412733
A33: BUSINESS INSIGHTS & RECOMMENDATIONS
A34: Sales Conversion: The current win rate is 21.76%. Analyzing lost deals and improving follow-ups can help convert more leads into successful sales.
A35: Revenue Performance: Total revenue is ₹68,35,500, with 237 won deals. Monitoring monthly revenue trends can help identify high-performing periods and improve sales planning.
A36: Customer Support: The average first response time is 6 hours, while the average resolution time is 8.77 hours. Reducing response and resolution delays can improve customer support efficiency.
A37: Customer Satisfaction: The average CSAT score is 4.04 out of 5. Maintaining service quality and addressing customer concerns can help improve satisfaction.
A38: Sales Pipeline: The Proposal stage has 245 records, compared with 237 won deals. Strengthening follow-ups and tracking deal progress can help improve conversions.

Sheet pivot table
A5: Row Labels | B5: Sum of Revenue_INR | C5: Sum of Deals | F5: Row Labels | G5: Sum of Revenue_INR | J5: Row Labels | K5: Sum of Deals | L5: Sum of Deal_Value_INR
A6: Aarav | B6: 746200 | C6: 139 | F6: Apr 2026 | G6: 857200 | J6: Demo Scheduled | K6: 149 | L6: 3788700
A7: Aditya | B7: 0 | C7: 0 | F7: Aug 2026 | G7: 556300 | J7: Lost | K7: 146 | L7: 4716000
A8: Ananya | B8: 0 | C8: 0 | F8: Dec 2025 | G8: 565700 | J8: Negotiation | K8: 152 | L8: 4375800
A9: Arjun | B9: 587800 | C9: 122 | F9: Feb 2026 | G9: 448100 | J9: Proposal | K9: 245 | L9: 7294400
A10: Diya | B10: 1069600 | C10: 145 | F10: Jan 2026 | G10: 382000 | J10: Qualified | K10: 160 | L10: 4598800
A11: Ishita | B11: 1049400 | C11: 166 | F11: Jul 2026 | G11: 1100700 | J11: Won | K11: 237 | L11: 6835500
A12: Kabir | B12: 1308200 | C12: 123 | F12: Jun 2026 | G12: 383100 | J12: (blank) | K12: 0 | L12: 0
A13: Karan | B13: 0 | C13: 0 | F13: Mar 2026 | G13: 713700 | J13: Grand Total | K13: 1089 | L13: 31609200
A14: Meera | B14: 617000 | C14: 131 | F14: May 2026 | G14: 379300
A15: Nisha | B15: 894100 | C15: 141 | F15: Nov 2025 | G15: 709100
A16: Pooja | B16: 0 | C16: 0 | F16: Oct 2025 | G16: 544000
A17: Priya | B17: 0 | C17: 0 | F17: Sep 2025 | G17: 196300
A18: Rahul | B18: 0 | C18: 0 | F18: Grand Total | G18: 6835500
A19: Rohan | B19: 563200 | C19: 122
A20: Sneha | B20: 0 | C20: 0
A21: Vivek | B21: 0 | C21: 0
A22: Grand Total | B22: 6835500 | C22: 1089
A30: Row Labels | B30: Sum of Tickets | C30: Average of First_Response_Hours | D30: Average of CSAT
A31: Closed | B31: 218 | C31: 5.8146789 | D31: 4.0444954
A32: Demo Scheduled | C32: 11.850336
A33: Escalated | B33: 92 | C33: 5.2945652 | D33: 4.0119565
A34: Lost | C34: 12.088356
A35: Negotiation | C35: 12.692763
A36: Pending | B36: 156 | C36: 5.9692308 | D36: 4.0371795
A37: Proposal | C37: 12.313061
A38: Qualified | C38: 12.164375
A39: Resolved | B39: 445 | C39: 6.2483146 | D39: 4.047191
A40: Won | C40: 11.827848
A41: Grand Total | B41: 911 | C41: 9.34625 | D41: 4.0412733
A48: Row Labels | B48: Sum of Revenue_INR
A49: India | B49: 3220200
A50: SEA | B50: 703600
A51: UAE | B51: 1721100
A52: UK | B52: 358800
A53: USA | B53: 831800
A54: Grand Total | B54: 6835500

Sheet pivot_dashboard
A1: SALES & CUSTOMER SUPPORT INSIGHTS
A8: Total Revenue | C8: Deals Won | E8: Win Rate | G8: Average CSAT
A9: =GETPIVOTDATA("Sum of Revenue_INR",'pivot table'!$A$5) -> 6835500 | C9: =GETPIVOTDATA("Sum of Deals",'pivot table'!$J$5,"Sales_Stage","Won") -> 237 | E9: =C9/GETPIVOTDATA("Sum of Deals",'pivot table'!$J$5) -> 0.21763085 | G9: =GETPIVOTDATA("Average of CSAT",'pivot table'!$A$30) -> 4.0412733

Sheet VLOOKUP_Analysis
A1: SALES & CUSTOMER SUPPORT
A2: RECORD LOOKUP SYSTEM
A3: Search for a record using VLOOKUP
A5: Enter Record_ID | B5: INT-00001
A7: RECORD DETAILS
A8: Owner | B8: =IF($B$5="","Enter Record_ID",IFERROR(VLOOKUP($B$5,cleaned!$A$2:$Q$2001,4,FALSE),"Record ID not found")) -> Ishita
A9: Team | B9: =IF($B$5="","Enter Record_ID",IFERROR(VLOOKUP($B$5,cleaned!$A$2:$Q$2001,3,FALSE),"Record ID not found")) -> Sales
A10: Region | B10: =IF($B$5="","Enter Record_ID",IFERROR(VLOOKUP($B$5,cleaned!$A$2:$Q$2001,5,FALSE),"Record ID not found")) -> India
A11: Customer | B11: =IF($B$5="","Enter Record_ID",IFERROR(VLOOKUP($B$5,cleaned!$A$2:$Q$2001,6,FALSE),"Record ID not found")) -> Customer 220
A12: Product | B12: =IF($B$5="","Enter Record_ID",IFERROR(VLOOKUP($B$5,cleaned!$A$2:$Q$2001,7,FALSE),"Record ID not found")) -> CRM
A13: Sales Stage | B13: =IF($B$5="","Enter Record_ID",IFERROR(VLOOKUP($B$5,cleaned!$A$2:$Q$2001,9,FALSE),"Record ID not found")) -> Won
A14: Deals | B14: =IF($B$5="","Enter Record_ID",IFERROR(VLOOKUP($B$5,cleaned!$A$2:$Q$2001,10,FALSE),"Record ID not found")) -> 1
A15: Deal Value | B15: =IF($B$5="","Enter Record_ID",IFERROR(VLOOKUP($B$5,cleaned!$A$2:$Q$2001,11,FALSE),"Record ID not found")) -> 67500
A16: Revenue | B16: =IF($B$5="","Enter Record_ID",IFERROR(VLOOKUP($B$5,cleaned!$A$2:$Q$2001,12,FALSE),"Record ID not found")) -> 67500
A17: Tickets | B17: =IF($B$5="","Enter Record_ID",IFERROR(VLOOKUP($B$5,cleaned!$A$2:$Q$2001,13,FALSE),"Record ID not found")) -> 0
A18: First Response (Hours) | B18: =IF($B$5="","Enter Record_ID",IFERROR(VLOOKUP($B$5,cleaned!$A$2:$Q$2001,14,FALSE),"Record ID not found")) -> 2
A19: Resolution (Hours) | B19: =IF($B$5="","Enter Record_ID",IFERROR(VLOOKUP($B$5,cleaned!$A$2:$Q$2001,15,FALSE),"Record ID not found")) -> 0
A20: Customer Satisfaction | B20: =IF($B$5="","Enter Record_ID",IFERROR(VLOOKUP($B$5,cleaned!$A$2:$Q$2001,16,FALSE),"Record ID not found")) -> 0
A21: Status | B21: =IF($B$5="","Enter Record_ID",IFERROR(VLOOKUP($B$5,cleaned!$A$2:$Q$2001,17,FALSE),"Record ID not found")) -> Won

Sheet What_If_Analysis
A1: SALES SCENARIO ANALYSIS
A2: Revenue Planning & Target Analysis
A4: Current Revenue | B4: =summary!F6 -> 6835500
A5: Expected Growth % | B5: -0.85370492
A6: Projected Revenue | B6: =B4*(1+B5) -> 1000000
A7: Revenue Target | B7: 1000000
A8: Target Gap | B8: =B7-B6 -> 0
